{
 "cells": [
  {
   "cell_type": "code",
   "execution_count": 3,
   "id": "944a2d5c-b8bf-4100-a49a-0b4823354a73",
   "metadata": {},
   "outputs": [
    {
     "name": "stderr",
     "output_type": "stream",
     "text": [
      "\n",
      "A module that was compiled using NumPy 1.x cannot be run in\n",
      "NumPy 2.2.3 as it may crash. To support both 1.x and 2.x\n",
      "versions of NumPy, modules must be compiled with NumPy 2.0.\n",
      "Some module may need to rebuild instead e.g. with 'pybind11>=2.12'.\n",
      "\n",
      "If you are a user of the module, the easiest solution will be to\n",
      "downgrade to 'numpy<2' or try to upgrade the affected module.\n",
      "We expect that some modules will need time to support NumPy 2.\n",
      "\n",
      "Traceback (most recent call last):  File \"/home/bosser/anaconda3/lib/python3.12/runpy.py\", line 198, in _run_module_as_main\n",
      "    return _run_code(code, main_globals, None,\n",
      "  File \"/home/bosser/anaconda3/lib/python3.12/runpy.py\", line 88, in _run_code\n",
      "    exec(code, run_globals)\n",
      "  File \"/home/bosser/anaconda3/lib/python3.12/site-packages/ipykernel_launcher.py\", line 18, in <module>\n",
      "    app.launch_new_instance()\n",
      "  File \"/home/bosser/anaconda3/lib/python3.12/site-packages/traitlets/config/application.py\", line 1075, in launch_instance\n",
      "    app.start()\n",
      "  File \"/home/bosser/anaconda3/lib/python3.12/site-packages/ipykernel/kernelapp.py\", line 739, in start\n",
      "    self.io_loop.start()\n",
      "  File \"/home/bosser/anaconda3/lib/python3.12/site-packages/tornado/platform/asyncio.py\", line 205, in start\n",
      "    self.asyncio_loop.run_forever()\n",
      "  File \"/home/bosser/anaconda3/lib/python3.12/asyncio/base_events.py\", line 641, in run_forever\n",
      "    self._run_once()\n",
      "  File \"/home/bosser/anaconda3/lib/python3.12/asyncio/base_events.py\", line 1986, in _run_once\n",
      "    handle._run()\n",
      "  File \"/home/bosser/anaconda3/lib/python3.12/asyncio/events.py\", line 88, in _run\n",
      "    self._context.run(self._callback, *self._args)\n",
      "  File \"/home/bosser/anaconda3/lib/python3.12/site-packages/ipykernel/kernelbase.py\", line 545, in dispatch_queue\n",
      "    await self.process_one()\n",
      "  File \"/home/bosser/anaconda3/lib/python3.12/site-packages/ipykernel/kernelbase.py\", line 534, in process_one\n",
      "    await dispatch(*args)\n",
      "  File \"/home/bosser/anaconda3/lib/python3.12/site-packages/ipykernel/kernelbase.py\", line 437, in dispatch_shell\n",
      "    await result\n",
      "  File \"/home/bosser/anaconda3/lib/python3.12/site-packages/ipykernel/ipkernel.py\", line 362, in execute_request\n",
      "    await super().execute_request(stream, ident, parent)\n",
      "  File \"/home/bosser/anaconda3/lib/python3.12/site-packages/ipykernel/kernelbase.py\", line 778, in execute_request\n",
      "    reply_content = await reply_content\n",
      "  File \"/home/bosser/anaconda3/lib/python3.12/site-packages/ipykernel/ipkernel.py\", line 449, in do_execute\n",
      "    res = shell.run_cell(\n",
      "  File \"/home/bosser/anaconda3/lib/python3.12/site-packages/ipykernel/zmqshell.py\", line 549, in run_cell\n",
      "    return super().run_cell(*args, **kwargs)\n",
      "  File \"/home/bosser/anaconda3/lib/python3.12/site-packages/IPython/core/interactiveshell.py\", line 3075, in run_cell\n",
      "    result = self._run_cell(\n",
      "  File \"/home/bosser/anaconda3/lib/python3.12/site-packages/IPython/core/interactiveshell.py\", line 3130, in _run_cell\n",
      "    result = runner(coro)\n",
      "  File \"/home/bosser/anaconda3/lib/python3.12/site-packages/IPython/core/async_helpers.py\", line 128, in _pseudo_sync_runner\n",
      "    coro.send(None)\n",
      "  File \"/home/bosser/anaconda3/lib/python3.12/site-packages/IPython/core/interactiveshell.py\", line 3334, in run_cell_async\n",
      "    has_raised = await self.run_ast_nodes(code_ast.body, cell_name,\n",
      "  File \"/home/bosser/anaconda3/lib/python3.12/site-packages/IPython/core/interactiveshell.py\", line 3517, in run_ast_nodes\n",
      "    if await self.run_code(code, result, async_=asy):\n",
      "  File \"/home/bosser/anaconda3/lib/python3.12/site-packages/IPython/core/interactiveshell.py\", line 3577, in run_code\n",
      "    exec(code_obj, self.user_global_ns, self.user_ns)\n",
      "  File \"/tmp/ipykernel_15105/2010272580.py\", line 2, in <module>\n",
      "    import pandas as pd\n",
      "  File \"/home/bosser/anaconda3/lib/python3.12/site-packages/pandas/__init__.py\", line 26, in <module>\n",
      "    from pandas.compat import (\n",
      "  File \"/home/bosser/anaconda3/lib/python3.12/site-packages/pandas/compat/__init__.py\", line 27, in <module>\n",
      "    from pandas.compat.pyarrow import (\n",
      "  File \"/home/bosser/anaconda3/lib/python3.12/site-packages/pandas/compat/pyarrow.py\", line 8, in <module>\n",
      "    import pyarrow as pa\n",
      "  File \"/home/bosser/anaconda3/lib/python3.12/site-packages/pyarrow/__init__.py\", line 65, in <module>\n",
      "    import pyarrow.lib as _lib\n"
     ]
    },
    {
     "ename": "ImportError",
     "evalue": "\nA module that was compiled using NumPy 1.x cannot be run in\nNumPy 2.2.3 as it may crash. To support both 1.x and 2.x\nversions of NumPy, modules must be compiled with NumPy 2.0.\nSome module may need to rebuild instead e.g. with 'pybind11>=2.12'.\n\nIf you are a user of the module, the easiest solution will be to\ndowngrade to 'numpy<2' or try to upgrade the affected module.\nWe expect that some modules will need time to support NumPy 2.\n\n",
     "output_type": "error",
     "traceback": [
      "\u001b[0;31m---------------------------------------------------------------------------\u001b[0m",
      "\u001b[0;31mImportError\u001b[0m                               Traceback (most recent call last)",
      "File \u001b[0;32m~/anaconda3/lib/python3.12/site-packages/numpy/core/_multiarray_umath.py:44\u001b[0m, in \u001b[0;36m__getattr__\u001b[0;34m(attr_name)\u001b[0m\n\u001b[1;32m     39\u001b[0m     \u001b[38;5;66;03m# Also print the message (with traceback).  This is because old versions\u001b[39;00m\n\u001b[1;32m     40\u001b[0m     \u001b[38;5;66;03m# of NumPy unfortunately set up the import to replace (and hide) the\u001b[39;00m\n\u001b[1;32m     41\u001b[0m     \u001b[38;5;66;03m# error.  The traceback shouldn't be needed, but e.g. pytest plugins\u001b[39;00m\n\u001b[1;32m     42\u001b[0m     \u001b[38;5;66;03m# seem to swallow it and we should be failing anyway...\u001b[39;00m\n\u001b[1;32m     43\u001b[0m     sys\u001b[38;5;241m.\u001b[39mstderr\u001b[38;5;241m.\u001b[39mwrite(msg \u001b[38;5;241m+\u001b[39m tb_msg)\n\u001b[0;32m---> 44\u001b[0m     \u001b[38;5;28;01mraise\u001b[39;00m \u001b[38;5;167;01mImportError\u001b[39;00m(msg)\n\u001b[1;32m     46\u001b[0m ret \u001b[38;5;241m=\u001b[39m \u001b[38;5;28mgetattr\u001b[39m(_multiarray_umath, attr_name, \u001b[38;5;28;01mNone\u001b[39;00m)\n\u001b[1;32m     47\u001b[0m \u001b[38;5;28;01mif\u001b[39;00m ret \u001b[38;5;129;01mis\u001b[39;00m \u001b[38;5;28;01mNone\u001b[39;00m:\n",
      "\u001b[0;31mImportError\u001b[0m: \nA module that was compiled using NumPy 1.x cannot be run in\nNumPy 2.2.3 as it may crash. To support both 1.x and 2.x\nversions of NumPy, modules must be compiled with NumPy 2.0.\nSome module may need to rebuild instead e.g. with 'pybind11>=2.12'.\n\nIf you are a user of the module, the easiest solution will be to\ndowngrade to 'numpy<2' or try to upgrade the affected module.\nWe expect that some modules will need time to support NumPy 2.\n\n"
     ]
    },
    {
     "name": "stderr",
     "output_type": "stream",
     "text": [
      "\n",
      "A module that was compiled using NumPy 1.x cannot be run in\n",
      "NumPy 2.2.3 as it may crash. To support both 1.x and 2.x\n",
      "versions of NumPy, modules must be compiled with NumPy 2.0.\n",
      "Some module may need to rebuild instead e.g. with 'pybind11>=2.12'.\n",
      "\n",
      "If you are a user of the module, the easiest solution will be to\n",
      "downgrade to 'numpy<2' or try to upgrade the affected module.\n",
      "We expect that some modules will need time to support NumPy 2.\n",
      "\n",
      "Traceback (most recent call last):  File \"/home/bosser/anaconda3/lib/python3.12/runpy.py\", line 198, in _run_module_as_main\n",
      "    return _run_code(code, main_globals, None,\n",
      "  File \"/home/bosser/anaconda3/lib/python3.12/runpy.py\", line 88, in _run_code\n",
      "    exec(code, run_globals)\n",
      "  File \"/home/bosser/anaconda3/lib/python3.12/site-packages/ipykernel_launcher.py\", line 18, in <module>\n",
      "    app.launch_new_instance()\n",
      "  File \"/home/bosser/anaconda3/lib/python3.12/site-packages/traitlets/config/application.py\", line 1075, in launch_instance\n",
      "    app.start()\n",
      "  File \"/home/bosser/anaconda3/lib/python3.12/site-packages/ipykernel/kernelapp.py\", line 739, in start\n",
      "    self.io_loop.start()\n",
      "  File \"/home/bosser/anaconda3/lib/python3.12/site-packages/tornado/platform/asyncio.py\", line 205, in start\n",
      "    self.asyncio_loop.run_forever()\n",
      "  File \"/home/bosser/anaconda3/lib/python3.12/asyncio/base_events.py\", line 641, in run_forever\n",
      "    self._run_once()\n",
      "  File \"/home/bosser/anaconda3/lib/python3.12/asyncio/base_events.py\", line 1986, in _run_once\n",
      "    handle._run()\n",
      "  File \"/home/bosser/anaconda3/lib/python3.12/asyncio/events.py\", line 88, in _run\n",
      "    self._context.run(self._callback, *self._args)\n",
      "  File \"/home/bosser/anaconda3/lib/python3.12/site-packages/ipykernel/kernelbase.py\", line 545, in dispatch_queue\n",
      "    await self.process_one()\n",
      "  File \"/home/bosser/anaconda3/lib/python3.12/site-packages/ipykernel/kernelbase.py\", line 534, in process_one\n",
      "    await dispatch(*args)\n",
      "  File \"/home/bosser/anaconda3/lib/python3.12/site-packages/ipykernel/kernelbase.py\", line 437, in dispatch_shell\n",
      "    await result\n",
      "  File \"/home/bosser/anaconda3/lib/python3.12/site-packages/ipykernel/ipkernel.py\", line 362, in execute_request\n",
      "    await super().execute_request(stream, ident, parent)\n",
      "  File \"/home/bosser/anaconda3/lib/python3.12/site-packages/ipykernel/kernelbase.py\", line 778, in execute_request\n",
      "    reply_content = await reply_content\n",
      "  File \"/home/bosser/anaconda3/lib/python3.12/site-packages/ipykernel/ipkernel.py\", line 449, in do_execute\n",
      "    res = shell.run_cell(\n",
      "  File \"/home/bosser/anaconda3/lib/python3.12/site-packages/ipykernel/zmqshell.py\", line 549, in run_cell\n",
      "    return super().run_cell(*args, **kwargs)\n",
      "  File \"/home/bosser/anaconda3/lib/python3.12/site-packages/IPython/core/interactiveshell.py\", line 3075, in run_cell\n",
      "    result = self._run_cell(\n",
      "  File \"/home/bosser/anaconda3/lib/python3.12/site-packages/IPython/core/interactiveshell.py\", line 3130, in _run_cell\n",
      "    result = runner(coro)\n",
      "  File \"/home/bosser/anaconda3/lib/python3.12/site-packages/IPython/core/async_helpers.py\", line 128, in _pseudo_sync_runner\n",
      "    coro.send(None)\n",
      "  File \"/home/bosser/anaconda3/lib/python3.12/site-packages/IPython/core/interactiveshell.py\", line 3334, in run_cell_async\n",
      "    has_raised = await self.run_ast_nodes(code_ast.body, cell_name,\n",
      "  File \"/home/bosser/anaconda3/lib/python3.12/site-packages/IPython/core/interactiveshell.py\", line 3517, in run_ast_nodes\n",
      "    if await self.run_code(code, result, async_=asy):\n",
      "  File \"/home/bosser/anaconda3/lib/python3.12/site-packages/IPython/core/interactiveshell.py\", line 3577, in run_code\n",
      "    exec(code_obj, self.user_global_ns, self.user_ns)\n",
      "  File \"/tmp/ipykernel_15105/2010272580.py\", line 2, in <module>\n",
      "    import pandas as pd\n",
      "  File \"/home/bosser/anaconda3/lib/python3.12/site-packages/pandas/__init__.py\", line 49, in <module>\n",
      "    from pandas.core.api import (\n",
      "  File \"/home/bosser/anaconda3/lib/python3.12/site-packages/pandas/core/api.py\", line 9, in <module>\n",
      "    from pandas.core.dtypes.dtypes import (\n",
      "  File \"/home/bosser/anaconda3/lib/python3.12/site-packages/pandas/core/dtypes/dtypes.py\", line 24, in <module>\n",
      "    from pandas._libs import (\n",
      "  File \"/home/bosser/anaconda3/lib/python3.12/site-packages/pyarrow/__init__.py\", line 65, in <module>\n",
      "    import pyarrow.lib as _lib\n"
     ]
    },
    {
     "ename": "ImportError",
     "evalue": "\nA module that was compiled using NumPy 1.x cannot be run in\nNumPy 2.2.3 as it may crash. To support both 1.x and 2.x\nversions of NumPy, modules must be compiled with NumPy 2.0.\nSome module may need to rebuild instead e.g. with 'pybind11>=2.12'.\n\nIf you are a user of the module, the easiest solution will be to\ndowngrade to 'numpy<2' or try to upgrade the affected module.\nWe expect that some modules will need time to support NumPy 2.\n\n",
     "output_type": "error",
     "traceback": [
      "\u001b[0;31m---------------------------------------------------------------------------\u001b[0m",
      "\u001b[0;31mImportError\u001b[0m                               Traceback (most recent call last)",
      "File \u001b[0;32m~/anaconda3/lib/python3.12/site-packages/numpy/core/_multiarray_umath.py:44\u001b[0m, in \u001b[0;36m__getattr__\u001b[0;34m(attr_name)\u001b[0m\n\u001b[1;32m     39\u001b[0m     \u001b[38;5;66;03m# Also print the message (with traceback).  This is because old versions\u001b[39;00m\n\u001b[1;32m     40\u001b[0m     \u001b[38;5;66;03m# of NumPy unfortunately set up the import to replace (and hide) the\u001b[39;00m\n\u001b[1;32m     41\u001b[0m     \u001b[38;5;66;03m# error.  The traceback shouldn't be needed, but e.g. pytest plugins\u001b[39;00m\n\u001b[1;32m     42\u001b[0m     \u001b[38;5;66;03m# seem to swallow it and we should be failing anyway...\u001b[39;00m\n\u001b[1;32m     43\u001b[0m     sys\u001b[38;5;241m.\u001b[39mstderr\u001b[38;5;241m.\u001b[39mwrite(msg \u001b[38;5;241m+\u001b[39m tb_msg)\n\u001b[0;32m---> 44\u001b[0m     \u001b[38;5;28;01mraise\u001b[39;00m \u001b[38;5;167;01mImportError\u001b[39;00m(msg)\n\u001b[1;32m     46\u001b[0m ret \u001b[38;5;241m=\u001b[39m \u001b[38;5;28mgetattr\u001b[39m(_multiarray_umath, attr_name, \u001b[38;5;28;01mNone\u001b[39;00m)\n\u001b[1;32m     47\u001b[0m \u001b[38;5;28;01mif\u001b[39;00m ret \u001b[38;5;129;01mis\u001b[39;00m \u001b[38;5;28;01mNone\u001b[39;00m:\n",
      "\u001b[0;31mImportError\u001b[0m: \nA module that was compiled using NumPy 1.x cannot be run in\nNumPy 2.2.3 as it may crash. To support both 1.x and 2.x\nversions of NumPy, modules must be compiled with NumPy 2.0.\nSome module may need to rebuild instead e.g. with 'pybind11>=2.12'.\n\nIf you are a user of the module, the easiest solution will be to\ndowngrade to 'numpy<2' or try to upgrade the affected module.\nWe expect that some modules will need time to support NumPy 2.\n\n"
     ]
    }
   ],
   "source": [
    "import mysql.connector\n",
    "import pandas as pd\n",
    "\n",
    "# Definir la consulta de modificación\n",
    "query_modificacion = \"ALTER TABLE ofertas ADD COLUMN cluster NUMERIC NULL;\"\n",
    "\n",
    "config = toml.load(\"../.streamlit/secrets.toml\")\n",
    "db_config = config[\"database\"]\n",
    "\n",
    "db = mysql.connector.connect(host=db_config[\"host\"],\n",
    "                             user=db_config[\"user\"],\n",
    "                             password=db_config[\"password\"],\n",
    "                             database=db_config[\"database\"]) \n",
    "cursor = db.cursor()\n",
    "cursor.execute(query_modificacion)\n",
    "cursor.close()\n",
    "db.close()"
   ]
  },
  {
   "cell_type": "code",
   "execution_count": null,
   "id": "da43d59a-cce1-4295-95be-882ef6526959",
   "metadata": {},
   "outputs": [],
   "source": []
  }
 ],
 "metadata": {
  "kernelspec": {
   "display_name": "Python 3 (ipykernel)",
   "language": "python",
   "name": "python3"
  },
  "language_info": {
   "codemirror_mode": {
    "name": "ipython",
    "version": 3
   },
   "file_extension": ".py",
   "mimetype": "text/x-python",
   "name": "python",
   "nbconvert_exporter": "python",
   "pygments_lexer": "ipython3",
   "version": "3.12.7"
  }
 },
 "nbformat": 4,
 "nbformat_minor": 5
}
